Workbook

Sheet Leia-me
B2: FAST Insights — modelo financeiro
B3: Suporte quantitativo ao business plan · Rodrigo Garcia, franqueado FAST Limão · 08/09/2026
A6: COMO USAR
B7: 1. Mude só o azul | C7: Toda célula com texto AZUL na aba Premissas é uma entrada que você pode editar. Células pretas são fórmulas — não digite por cima delas.
B8: 2. Fundo amarelo = decisivo | C8: As entradas com fundo amarelo são as que mais mexem no resultado. Comece por elas.
B9: 3. O resto se ajusta sozinho | C9: Modelo mensal, Resumo e Cenários recalculam a partir das Premissas. Nenhum número deste arquivo é digitado duas vezes.
B10: 4. Se abrir e vier vazio | C10: Alguns visualizadores não recalculam sozinhos. Abra no Excel, LibreOffice ou Google Sheets e mande recalcular (no Excel: Ctrl+Alt+F9).
A12: AS ABAS
B13: Premissas | C13: Todas as entradas do modelo, agrupadas por tema, com a fonte de cada número.
B14: Modelo mensal | C14: 36 meses, linha a linha: lojas, receita, custos, resultado e caixa acumulado.
B15: Resumo | C15: Os números de decisão — capital necessário, ponto de equilíbrio, economia unitária — e os dois gráficos.
B16: Cenários | C16: Nove cenários calculados ao vivo, inclusive os de participação da franqueadora na receita.
B17: Descoberta | C17: Os 34 itens que faltam validar. Marque o status e anote a resposta.
A19: LEGENDA DE CORES
B20: Azul | C20: Número digitado — é uma premissa, e você pode mudar.
B21: Preto | C21: Fórmula calculada dentro da própria aba.
B22: Verde | C22: Fórmula que busca valor em outra aba.
B23: Fundo amarelo | C23: Premissa decisiva, ou campo para você preencher.
A25: TRÊS AVISOS HONESTOS
B26: Projeção, não previsão | C26: Cada linha aqui é uma suposição explícita. As que ainda não foram verificadas estão na aba Descoberta — seis delas são bloqueantes.
B27: Antes de impostos, por padrão | C27: A alíquota sobre a receita da empresa de software vem zerada (item N3 da Descoberta). Preencha-a em Premissas assim que o contador responder: no Simples, algo entre 6% e 16%.
B28: Adoção já é líquida de churn | C28: A curva de adoção representa lojas ativas, já descontando quem sai. O churn das Premissas serve só para calcular o LTV.

Sheet Premissas
A1: Premissas
A2: Edite apenas as células azuis. A célula B7 escolhe o modelo comercial e reconfigura sete premissas de uma vez.
A4: Premissa | B4: Em uso | C4: Sem homologação | D4: Com homologação | E4: Origem / observação
A6: MODELO COMERCIAL — a chave que muda tudo
A7: Modelo em uso (1 = COM homologação · 0 = SEM homologação) | B7: 1 | E7: 1 = homologado obrigatório em toda a rede, com cobrança consolidada pela franqueadora. 0 = venda voluntária, loja a loja. Trocar aqui reconfigura as sete linhas abaixo de uma vez.
C8: Sem homologação | D8: Com homologação
A9: Preço por loja | B9: =IF($B$7=1,D9,C9) -> 299 | C9: =B24 -> 319 | D9: 299 | E9: Sem homologação vem do mix de planos; com homologação é preço único para a rede toda.
A10: Teto de adoção | B10: =IF($B$7=1,D10,C10) -> 0.95 | C10: 0.65 | D10: 0.95 | E10: Obrigatório não é venda: os 5% que faltam são lojas em implantação e em transição.
A11: Mês central da curva | B11: =IF($B$7=1,D11,C11) -> 12 | C11: 16 | D11: 12 | E11: A franqueadora marca prazo — não há convencimento loja a loja.
A12: Inclinação da curva | B12: =IF($B$7=1,D12,C12) -> 0.45 | C12: 0.32 | D12: 0.45 | E12: Implantação em bloco, não gota a gota.
A13: CAC por loja | B13: =IF($B$7=1,D13,C13) -> 50 | C13: 400 | D13: 50 | E13: Sem esforço de venda, sobra só o onboarding.
A14: Cobrança por loja | B14: =IF($B$7=1,D14,C14) -> 0 | C14: 3 | D14: 0 | E14: No consolidado é uma fatura só: a taxa por loja desaparece.
A15: Participação da franqueadora | B15: =IF($B$7=1,D15,C15) -> 0.25 | C15: 0 | D15: 0.25 | E15: O que a franqueadora cobra para tornar obrigatório e cobrar das lojas por você.
A17: PLANOS E MIX — usados apenas no modelo SEM homologação
A18: Plano | B18: Preço R$/mês | C18: Mix
A19: Essencial | B19: 199 | C19: 0.4
A20: Gestão | B20: 349 | C20: 0.45
A21: Crescimento | B21: 549 | C21: 0.15
A22: Soma do mix (precisa dar 100%) | C22: =SUM(C19:C21) -> 1
A24: Ticket médio do mix | B24: =SUMPRODUCT(B19:B21,C19:C21) -> 319 | E24: É este o preço usado quando B7 = 0.
A26: CUSTO POR LOJA
A27: Infraestrutura | B27: 8 | C27: R$/mês | E27: Servidor, banco e armazenamento rateados. A medir no piloto (item P1).
A28: Suporte | B28: 34 | C28: R$/mês | E28: 1 pessoa de CS para ~175 lojas. A medir no piloto (item N2).
A29: Cobrança | B29: =Premissas!$B$14 -> 0 | C29: R$/mês | E29: Vem do bloco Modelo comercial (linha 14).
A30: API / parceria de dados | B30: 0 | C30: R$/mês | E30: Zero enquanto a cota for do plano da loja. Itens T2 e T4 da Descoberta.
A31: Custo variável total | B31: =SUM(B27:B30) -> 42 | C31: R$/mês | E31: Soma das quatro linhas acima.
A32: Margem de contribuição | B32: =Premissas!$B$9-B31 -> 257 | C32: R$/mês | E32: Preço por loja menos custo variável.
A33: Margem de contribuição % | B33: =IF(Premissas!$B$9=0,0,B32/Premissas!$B$9) -> 0.85953177 | C33: %
A35: RETENÇÃO
A36: Churn mensal | B36: 0.015 | C36: %/mês | E36: Conservador; inclui fechamento de loja. Usado só no LTV — a curva de adoção já é líquida. No modelo obrigatório o churn real tende a ser menor ainda.
A38: REDE E CRONOGRAMA
A39: Lojas na rede hoje | B39: 431 | C39: lojas | E39: Fast Escova 401 + Fast Spa 30 em operação no fim de 2026. Fonte: Times Brasil / Mapa das Franquias, 09/2026.
A40: Lojas na rede no mês 36 | B40: 600 | C40: lojas | E40: Plano de expansão: +159 lojas em 2026. Fonte: mesma acima.
A41: Mês em que começam as vendas | B41: 7 | C41: mês | E41: Depois do acordo jurídico e do piloto.
A42: Atraso na homologação | B42: 0 | C42: meses | E42: Empurra todo o cronograma. Teste 6 para ver o efeito de a franqueadora demorar.
A44: PAINEL DA REDE (FRANQUEADORA)
A45: Mensalidade | B45: 10000 | C45: R$/mês | E45: Meio da faixa proposta de R$ 8 a 15 mil.
A46: Mês de início | B46: 9 | C46: mês | E46: Depois da Fase 2, quando o painel da rede existe.
A48: CUSTO FIXO POR FASE
A49: Fase 0 — até o mês 2 | B49: 5000 | C49: R$/mês | E49: Jurídico e negociação.
...

Sheet Modelo mensal
A1: Modelo mensal — 36 meses
A2: Todas as colunas são fórmulas que leem a aba Premissas. Custos aparecem como negativos.
A4: Mês | B4: Lojas na rede | C4: Lojas pagando | D4: Novas no mês | E4: Receita planos | F4: Painel da Rede | G4: Receita total | H4: Impostos | I4: Custo variável | J4: Custo fixo | K4: Investimento | L4: Resultado | M4: Caixa acumulado | N4: 1º mês positivo | O4: 1º mês caixa > 0
A5: 1 | B5: =Premissas!$B$39+(Premissas!$B$40-Premissas!$B$39)*A5/36 -> 435.69444 | C5: =IF(A5-Premissas!$B$42<Premissas!$B$41,0,Premissas!$B$10*B5/(1+EXP(-Premissas!$B$12*(A5-Premissas!$B$42-Premissas!$B$11)))) -> 0 | D5: =C5 -> 0 | E5: =C5*Premissas!$B$9*(1-Premissas!$B$15) -> 0 | F5: =IF(A5>=Premissas!$B$46+Premissas!$B$42,Premissas!$B$45*(1-Premissas!$B$15),0) -> 0 | G5: =E5+F5 -> 0 | H5: =-G5*Premissas!$B$60 -> 0 | I5: =-(C5*Premissas!$B$31+D5*Premissas!$B$13) -> 0 | J5: =-IF(A5-Premissas!$B$42<=2,Premissas!$B$49,IF(A5-Premissas!$B$42<=5,Premissas!$B$50,IF(A5-Premissas!$B$42<=8,Premissas!$B$51,Premissas!$B$52))) -> -5000 | K5: =-IF(A5=1+Premissas!$B$42,Premissas!$B$55,IF(A5=3+Premissas!$B$42,Premissas!$B$56,IF(A5=6+Premissas!$B$42,Premissas!$B$57,0))) -> -8000 | L5: =G5+H5+I5+J5+K5 -> -13000 | M5: =L5 -> -13000 | N5: =IF(L5>0,A5,9999) -> 9999 | O5: =IF(M5>0,A5,9999) -> 9999
A6: 2 | B6: =Premissas!$B$39+(Premissas!$B$40-Premissas!$B$39)*A6/36 -> 440.38889 | C6: =IF(A6-Premissas!$B$42<Premissas!$B$41,0,Premissas!$B$10*B6/(1+EXP(-Premissas!$B$12*(A6-Premissas!$B$42-Premissas!$B$11)))) -> 0 | D6: =MAX(0,C6-C5) -> 0 | E6: =C6*Premissas!$B$9*(1-Premissas!$B$15) -> 0 | F6: =IF(A6>=Premissas!$B$46+Premissas!$B$42,Premissas!$B$45*(1-Premissas!$B$15),0) -> 0 | G6: =E6+F6 -> 0 | H6: =-G6*Premissas!$B$60 -> 0 | I6: =-(C6*Premissas!$B$31+D6*Premissas!$B$13) -> 0 | J6: =-IF(A6-Premissas!$B$42<=2,Premissas!$B$49,IF(A6-Premissas!$B$42<=5,Premissas!$B$50,IF(A6-Premissas!$B$42<=8,Premissas!$B$51,Premissas!$B$52))) -> -5000 | K6: =-IF(A6=1+Premissas!$B$42,Premissas!$B$55,IF(A6=3+Premissas!$B$42,Premissas!$B$56,IF(A6=6+Premissas!$B$42,Premissas!$B$57,0))) -> 0 | L6: =G6+H6+I6+J6+K6 -> -5000 | M6: =M5+L6 -> -18000 | N6: =IF(L6>0,A6,9999) -> 9999 | O6: =IF(M6>0,A6,9999) -> 9999
A7: 3 | B7: =Premissas!$B$39+(Premissas!$B$40-Premissas!$B$39)*A7/36 -> 445.08333 | C7: =IF(A7-Premissas!$B$42<Premissas!$B$41,0,Premissas!$B$10*B7/(1+EXP(-Premissas!$B$12*(A7-Premissas!$B$42-Premissas!$B$11)))) -> 0 | D7: =MAX(0,C7-C6) -> 0 | E7: =C7*Premissas!$B$9*(1-Premissas!$B$15) -> 0 | F7: =IF(A7>=Premissas!$B$46+Premissas!$B$42,Premissas!$B$45*(1-Premissas!$B$15),0) -> 0 | G7: =E7+F7 -> 0 | H7: =-G7*Premissas!$B$60 -> 0 | I7: =-(C7*Premissas!$B$31+D7*Premissas!$B$13) -> 0 | J7: =-IF(A7-Premissas!$B$42<=2,Premissas!$B$49,IF(A7-Premissas!$B$42<=5,Premissas!$B$50,IF(A7-Premissas!$B$42<=8,Premissas!$B$51,Premissas!$B$52))) -> -22000 | K7: =-IF(A7=1+Premissas!$B$42,Premissas!$B$55,IF(A7=3+Premissas!$B$42,Premissas!$B$56,IF(A7=6+Premissas!$B$42,Premissas!$B$57,0))) -> -12000 | L7: =G7+H7+I7+J7+K7 -> -34000 | M7: =M6+L7 -> -52000 | N7: =IF(L7>0,A7,9999) -> 9999 | O7: =IF(M7>0,A7,9999) -> 9999
A8: 4 | B8: =Premissas!$B$39+(Premissas!$B$40-Premissas!$B$39)*A8/36 -> 449.77778 | C8: =IF(A8-Premissas!$B$42<Premissas!$B$41,0,Premissas!$B$10*B8/(1+EXP(-Premissas!$B$12*(A8-Premissas!$B$42-Premissas!$B$11)))) -> 0 | D8: =MAX(0,C8-C7) -> 0 | E8: =C8*Premissas!$B$9*(1-Premissas!$B$15) -> 0 | F8: =IF(A8>=Premissas!$B$46+Premissas!$B$42,Premissas!$B$45*(1-Premissas!$B$15),0) -> 0 | G8: =E8+F8 -> 0 | H8: =-G8*Premissas!$B$60 -> 0 | I8: =-(C8*Premissas!$B$31+D8*Premissas!$B$13) -> 0 | J8: =-IF(A8-Premissas!$B$42<=2,Premissas!$B$49,IF(A8-Premissas!$B$42<=5,Premissas!$B$50,IF(A8-Premissas!$B$42<=8,Premissas!$B$51,Premissas!$B$52))) -> -22000 | K8: =-IF(A8=1+Premissas!$B$42,Premissas!$B$55,IF(A8=3+Premissas!$B$42,Premissas!$B$56,IF(A8=6+Premissas!$B$42,Premissas!$B$57,0))) -> 0 | L8: =G8+H8+I8+J8+K8 -> -22000 | M8: =M7+L8 -> -74000 | N8: =IF(L8>0,A8,9999) -> 9999 | O8: =IF(M8>0,A8,9999) -> 9999
A9: 5 | B9: =Premissas!$B$39+(Premissas!$B$40-Premissas!$B$39)*A9/36 -> 454.47222 | C9: =IF(A9-Premissas!$B$42<Premissas!$B$41,0,Premissas!$B$10*B9/(1+EXP(-Premissas!$B$12*(A9-Premissas!$B$42-Premissas!$B$11)))) -> 0 | D9: =MAX(0,C9-C8) -> 0 | E9: =C9*Premissas!$B$9*(1-Premissas!$B$15) -> 0 | F9: =IF(A9>=Premissas!$B$46+Premissas!$B$42,Premissas!$B$45*(1-Premissas!$B$15),0) -> 0 | G9: =E9+F9 -> 0 | H9: =-G9*Premissas!$B$60 -> 0 | I9: =-(C9*Premissas!$B$31+D9*Premissas!$B$13) -> 0 | J9: =-IF(A9-Premissas!$B$42<=2,Premissas!$B$49,IF(A9-Premissas!$B$42<=5,Premissas!$B$50,IF(A9-Premissas!$B$42<=8,Premissas!$B$51,Premissas!$B$52))) -> -22000 | K9: =-IF(A9=1+Premissas!$B$42,Premissas!$B$55,IF(A9=3+Premissas!$B$42,Premissas!$B$56,IF(A9=6+Premissas!$B$42,Premissas!$B$57,0))) -> 0 | L9: =G9+H9+I9+J9+K9 -> -22000 | M9: =M8+L9 -> -96000 | N9: =IF(L9>0,A9,9999) -> 9999 | O9: =IF(M9>0,A9,9999) -> 9999
A10: 6 | B10: =Premissas!$B$39+(Premissas!$B$40-Premissas!$B$39)*A10/36 -> 459.16667 | C10: =IF(A10-Premissas!$B$42<Premissas!$B$41,0,Premissas!$B$10*B10/(1+EXP(-Premissas!$B$12*(A10-Premissas!$B$42-Premissas!$B$11)))) -> 0 | D10: =MAX(0,C10-C9) -> 0 | E10: =C10*Premissas!$B$9*(1-Premissas!$B$15) -> 0 | F10: =IF(A10>=Premissas!$B$46+Premissas!$B$42,Premissas!$B$45*(1-Premissas!$B$15),0) -> 0 | G10: =E10+F10 -> 0 | H10: =-G10*Premissas!$B$60 -> 0 | I10: =-(C10*Premissas!$B$31+D10*Premissas!$B$13) -> 0 | J10: =-IF(A10-Premissas!$B$42<=2,Premissas!$B$49,IF(A10-Premissas!$B$42<=5,Premissas!$B$50,IF(A10-Premissas!$B$42<=8,Premissas!$B$51,Premissas!$B$52))) -> -28000 | K10: =-IF(A10=1+Premissas!$B$42,Premissas!$B$55,IF(A10=3+Premissas!$B$42,Premissas!$B$56,IF(A10=6+Premissas!$B$42,Premissas!$B$57,0))) -> -10000 | L10: =G10+H10+I10+J10+K10 -> -38000 | M10: =M9+L10 -> -134000 | N10: =IF(L10>0,A10,9999) -> 9999 | O10: =IF(M10>0,A10,9999) -> 9999
A11: 7 | B11: =Premissas!$B$39+(Premissas!$B$40-Premissas!$B$39)*A11/36 -> 463.86111 | C11: =IF(A11-Premissas!$B$42<Premissas!$B$41,0,Premissas!$B$10*B11/(1+EXP(-Premissas!$B$12*(A11-Premissas!$B$42-Premissas!$B$11)))) -> 42.017463 | D11: =MAX(0,C11-C10) -> 42.017463 | E11: =C11*Premissas!$B$9*(1-Premissas!$B$15) -> 9422.4161 | F11: =IF(A11>=Premissas!$B$46+Premissas!$B$42,Premissas!$B$45*(1-Premissas!$B$15),0) -> 0 | G11: =E11+F11 -> 9422.4161 | H11: =-G11*Premissas!$B$60 -> 0 | I11: =-(C11*Premissas!$B$31+D11*Premissas!$B$13) -> -3865.6066 | J11: =-IF(A11-Premissas!$B$42<=2,Premissas!$B$49,IF(A11-Premissas!$B$42<=5,Premissas!$B$50,IF(A11-Premissas!$B$42<=8,Premissas!$B$51,Premissas!$B$52))) -> -28000 | K11: =-IF(A11=1+Premissas!$B$42,Premissas!$B$55,IF(A11=3+Premissas!$B$42,Premissas!$B$56,IF(A11=6+Premissas!$B$42,Premissas!$B$57,0))) -> 0 | L11: =G11+H11+I11+J11+K11 -> -22443.19 | M11: =M10+L11 -> -156443.19 | N11: =IF(L11>0,A11,9999) -> 9999 | O11: =IF(M11>0,A11,9999) -> 9999
A12: 8 | B12: =Premissas!$B$39+(Premissas!$B$40-Premissas!$B$39)*A12/36 -> 468.55556 | C12: =IF(A12-Premissas!$B$42<Premissas!$B$41,0,Premissas!$B$10*B12/(1+EXP(-Premissas!$B$12*(A12-Premissas!$B$42-Premissas!$B$11)))) -> 63.141849 | D12: =MAX(0,C12-C11) -> 21.124386 | E12: =C12*Premissas!$B$9*(1-Premissas!$B$15) -> 14159.56 | F12: =IF(A12>=Premissas!$B$46+Premissas!$B$42,Premissas!$B$45*(1-Premissas!$B$15),0) -> 0 | G12: =E12+F12 -> 14159.56 | H12: =-G12*Premissas!$B$60 -> 0 | I12: =-(C12*Premissas!$B$31+D12*Premissas!$B$13) -> -3708.177 | J12: =-IF(A12-Premissas!$B$42<=2,Premissas!$B$49,IF(A12-Premissas!$B$42<=5,Premissas!$B$50,IF(A12-Premissas!$B$42<=8,Premissas!$B$51,Premissas!$B$52))) -> -28000 | K12: =-IF(A12=1+Premissas!$B$42,Premissas!$B$55,IF(A12=3+Premissas!$B$42,Premissas!$B$56,IF(A12=6+Premissas!$B$42,Premissas!$B$57,0))) -> 0 | L12: =G12+H12+I12+J12+K12 -> -17548.617 | M12: =M11+L12 -> -173991.81 | N12: =IF(L12>0,A12,9999) -> 9999 | O12: =IF(M12>0,A12,9999) -> 9999
A13: 9 | B13: =Premissas!$B$39+(Premissas!$B$40-Premissas!$B$39)*A13/36 -> 473.25 | C13: =IF(A13-Premissas!$B$42<Premissas!$B$41,0,Premissas!$B$10*B13/(1+EXP(-Premissas!$B$12*(A13-Premissas!$B$42-Premissas!$B$11)))) -> 92.556746 | D13: =MAX(0,C13-C12) -> 29.414896 | E13: =C13*Premissas!$B$9*(1-Premissas!$B$15) -> 20755.85 | F13: =IF(A13>=Premissas!$B$46+Premissas!$B$42,Premissas!$B$45*(1-Premissas!$B$15),0) -> 7500 | G13: =E13+F13 -> 28255.85 | H13: =-G13*Premissas!$B$60 -> 0 | I13: =-(C13*Premissas!$B$31+D13*Premissas!$B$13) -> -5358.1281 | J13: =-IF(A13-Premissas!$B$42<=2,Premissas!$B$49,IF(A13-Premissas!$B$42<=5,Premissas!$B$50,IF(A13-Premissas!$B$42<=8,Premissas!$B$51,Premissas!$B$52))) -> -35000 | K13: =-IF(A13=1+Premissas!$B$42,Premissas!$B$55,IF(A13=3+Premissas!$B$42,Premissas!$B$56,IF(A13=6+Premissas!$B$42,Premissas!$B$57,0))) -> 0 | L13: =G13+H13+I13+J13+K13 -> -12102.278 | M13: =M12+L13 -> -186094.09 | N13: =IF(L13>0,A13,9999) -> 9999 | O13: =IF(M13>0,A13,9999) -> 9999
A14: 10 | B14: =Premissas!$B$39+(Premissas!$B$40-Premissas!$B$39)*A14/36 -> 477.94444 | C14: =IF(A14-Premissas!$B$42<Premissas!$B$41,0,Premissas!$B$10*B14/(1+EXP(-Premissas!$B$12*(A14-Premissas!$B$42-Premissas!$B$11)))) -> 131.24258 | D14: =MAX(0,C14-C13) -> 38.68583 | E14: =C14*Premissas!$B$9*(1-Premissas!$B$15) -> 29431.148 | F14: =IF(A14>=Premissas!$B$46+Premissas!$B$42,Premissas!$B$45*(1-Premissas!$B$15),0) -> 7500 | G14: =E14+F14 -> 36931.148 | H14: =-G14*Premissas!$B$60 -> 0 | I14: =-(C14*Premissas!$B$31+D14*Premissas!$B$13) -> -7446.4796 | J14: =-IF(A14-Premissas!$B$42<=2,Premissas!$B$49,IF(A14-Premissas!$B$42<=5,Premissas!$B$50,IF(A14-Premissas!$B$42<=8,Premissas!$B$51,Premissas!$B$52))) -> -35000 | K14: =-IF(A14=1+Premissas!$B$42,Premissas!$B$55,IF(A14=3+Premissas!$B$42,Premissas!$B$56,IF(A14=6+Premissas!$B$42,Premissas!$B$57,0))) -> 0 | L14: =G14+H14+I14+J14+K14 -> -5515.3321 | M14: =M13+L14 -> -191609.42 | N14: =IF(L14>0,A14,9999) -> 9999 | O14: =IF(M14>0,A14,9999) -> 9999
A15: 11 | B15: =Premissas!$B$39+(Premissas!$B$40-Premissas!$B$39)*A15/36 -> 482.63889 | C15: =IF(A15-Premissas!$B$42<Premissas!$B$41,0,Premissas!$B$10*B15/(1+EXP(-Premissas!$B$12*(A15-Premissas!$B$42-Premissas!$B$11)))) -> 178.52462 | D15: =MAX(0,C15-C14) -> 47.28204 | E15: =C15*Premissas!$B$9*(1-Premissas!$B$15) -> 40034.145 | F15: =IF(A15>=Premissas!$B$46+Premissas!$B$42,Premissas!$B$45*(1-Premissas!$B$15),0) -> 7500 | G15: =E15+F15 -> 47534.145 | H15: =-G15*Premissas!$B$60 -> 0 | I15: =-(C15*Premissas!$B$31+D15*Premissas!$B$13) -> -9862.1358 | J15: =-IF(A15-Premissas!$B$42<=2,Premissas!$B$49,IF(A15-Premissas!$B$42<=5,Premissas!$B$50,IF(A15-Premissas!$B$42<=8,Premissas!$B$51,Premissas!$B$52))) -> -35000 | K15: =-IF(A15=1+Premissas!$B$42,Premissas!$B$55,IF(A15=3+Premissas!$B$42,Premissas!$B$56,IF(A15=6+Premissas!$B$42,Premissas!$B$57,0))) -> 0 | L15: =G15+H15+I15+J15+K15 -> 2672.0091 | M15: =M14+L15 -> -188937.41 | N15: =IF(L15>0,A15,9999) -> 11 | O15: =IF(M15>0,A15,9999) -> 9999
A16: 12 | B16: =Premissas!$B$39+(Premissas!$B$40-Premissas!$B$39)*A16/36 -> 487.33333 | C16: =IF(A16-Premissas!$B$42<Premissas!$B$41,0,Premissas!$B$10*B16/(1+EXP(-Premissas!$B$12*(A16-Premissas!$B$42-Premissas!$B$11)))) -> 231.48333 | D16: =MAX(0,C16-C15) -> 52.958718 | E16: =C16*Premissas!$B$9*(1-Premissas!$B$15) -> 51910.137 | F16: =IF(A16>=Premissas!$B$46+Premissas!$B$42,Premissas!$B$45*(1-Premissas!$B$15),0) -> 7500 | G16: =E16+F16 -> 59410.137 | H16: =-G16*Premissas!$B$60 -> 0 | I16: =-(C16*Premissas!$B$31+D16*Premissas!$B$13) -> -12370.236 | J16: =-IF(A16-Premissas!$B$42<=2,Premissas!$B$49,IF(A16-Premissas!$B$42<=5,Premissas!$B$50,IF(A16-Premissas!$B$42<=8,Premissas!$B$51,Premissas!$B$52))) -> -35000 | K16: =-IF(A16=1+Premissas!$B$42,Premissas!$B$55,IF(A16=3+Premissas!$B$42,Premissas!$B$56,IF(A16=6+Premissas!$B$42,Premissas!$B$57,0))) -> 0 | L16: =G16+H16+I16+J16+K16 -> 12039.902 | M16: =M15+L16 -> -176897.51 | N16: =IF(L16>0,A16,9999) -> 12 | O16: =IF(M16>0,A16,9999) -> 9999
A17: 13 | B17: =Premissas!$B$39+(Premissas!$B$40-Premissas!$B$39)*A17/36 -> 492.02778 | C17: =IF(A17-Premissas!$B$42<Premissas!$B$41,0,Premissas!$B$10*B17/(1+EXP(-Premissas!$B$12*(A17-Premissas!$B$42-Premissas!$B$11)))) -> 285.42889 | D17: =MAX(0,C17-C16) -> 53.945559 | E17: =C17*Premissas!$B$9*(1-Premissas!$B$15) -> 64007.429 | F17: =IF(A17>=Premissas!$B$46+Premissas!$B$42,Premissas!$B$45*(1-Premissas!$B$15),0) -> 7500 | G17: =E17+F17 -> 71507.429 | H17: =-G17*Premissas!$B$60 -> 0 | I17: =-(C17*Premissas!$B$31+D17*Premissas!$B$13) -> -14685.291 | J17: =-IF(A17-Premissas!$B$42<=2,Premissas!$B$49,IF(A17-Premissas!$B$42<=5,Premissas!$B$50,IF(A17-Premissas!$B$42<=8,Premissas!$B$51,Premissas!$B$52))) -> -35000 | K17: =-IF(A17=1+Premissas!$B$42,Premissas!$B$55,IF(A17=3+Premissas!$B$42,Premissas!$B$56,IF(A17=6+Premissas!$B$42,Premissas!$B$57,0))) -> 0 | L17: =G17+H17+I17+J17+K17 -> 21822.138 | M17: =M16+L17 -> -155075.37 | N17: =IF(L17>0,A17,9999) -> 13 | O17: =IF(M17>0,A17,9999) -> 9999
... A40: 36 | B40: =Premissas!$B$39+(Premissas!$B$40-Premissas!$B$39)*A40/36 -> 600 | C40: =IF(A40-Premissas!$B$42<Premissas!$B$41,0,Premissas!$B$10*B40/(1+EXP(-Premissas!$B$12*(A40-Premissas!$B$42-Premissas!$B$11)))) -> 569.98837 | D40: =MAX(0,C40-C39) -> 4.4661874 | E40: =C40*Premissas!$B$9*(1-Premissas!$B$15) -> 127819.89 | F40: =IF(A40>=Premissas!$B$46+Premissas!$B$42,Premissas!$B$45*(1-Premissas!$B$15),0) -> 7500 | G40: =E40+F40 -> 135319.89 | H40: =-G40*Premissas!$B$60 -> 0 | I40: =-(C40*Premissas!$B$31+D40*Premissas!$B$13) -> -24162.821 | J40: =-IF(A40-Premissas!$B$42<=2,Premissas!$B$49,IF(A40-Premissas!$B$42<=5,Premissas!$B$50,IF(A40-Premissas!$B$42<=8,Premissas!$B$51,Premissas!$B$52))) -> -35000 | K40: =-IF(A40=1+Premissas!$B$42,Premissas!$B$55,IF(A40=3+Premissas!$B$42,Premissas!$B$56,IF(A40=6+Premissas!$B$42,Premissas!$B$57,0))) -> 0 | L40: =G40+H40+I40+J40+K40 -> 76157.072 | M40: =M39+L40 -> 1302100.7 | N40: =IF(L40>0,A40,9999) -> 36 | O40: =IF(M40>0,A40,9999) -> 36
N42: Colunas auxiliares: 9999 = ainda não aconteceu.

Sheet Resumo
A1: Resumo — os números de decisão
A2: Tudo calculado a partir do Modelo mensal. Nada digitado.
A4: Indicador | B4: Valor | C4: Unidade | D4: Leitura
A6: CAIXA
A7: Capital necessário | B7: =-MIN('Modelo mensal'!M5:M40) -> 191609.42 | C7: R$ | D7: O ponto mais fundo do caixa. É o dinheiro que precisa existir antes de começar.
A8: Mês do pico de caixa negativo | B8: =INDEX('Modelo mensal'!A5:A40,MATCH(MIN('Modelo mensal'!M5:M40),'Modelo mensal'!M5:M40,0)) -> 10 | C8: mês
A9: 1º mês com resultado positivo | B9: =IF(MIN('Modelo mensal'!N5:N40)=9999,0,MIN('Modelo mensal'!N5:N40)) -> 11 | C9: mês | D9: Zero significa que não acontece em 36 meses.
A10: Mês em que o caixa volta a zero | B10: =IF(MIN('Modelo mensal'!O5:O40)=9999,0,MIN('Modelo mensal'!O5:O40)) -> 17 | C10: mês | D10: Zero significa que não volta em 36 meses.
A11: Caixa no mês 36 | B11: ='Modelo mensal'!M40 -> 1302100.7 | C11: R$
A13: RESULTADO POR ANO
A14: Ano | B14: Receita (antes de impostos) | C14: Resultado | D14: Lojas no fim do ano
A15: Ano 1 | B15: =SUM('Modelo mensal'!G5:G16) -> 195713.26 | C15: =SUM('Modelo mensal'!L5:L16) -> -176897.51 | D15: ='Modelo mensal'!C16 -> 231.48333
A16: Ano 2 | B16: =SUM('Modelo mensal'!G17:G28) -> 1275833.9 | C16: =SUM('Modelo mensal'!L17:L28) -> 619604.07 | D16: ='Modelo mensal'!C28 -> 514.16108
A17: Ano 3 | B17: =SUM('Modelo mensal'!G29:G40) -> 1556927.8 | C17: =SUM('Modelo mensal'!L29:L40) -> 859394.1 | D17: ='Modelo mensal'!C40 -> 569.98837
A19: PONTO DE EQUILÍBRIO
A20: Lojas necessárias — só os planos | B20: =IF(Premissas!$B$32=0,0,Premissas!$B$52/Premissas!$B$32) -> 136.18677 | C20: lojas | D20: Custo fixo em regime dividido pela margem de contribuição.
A21: Lojas necessárias — com o Painel da Rede | B21: =IF(Premissas!$B$32=0,0,MAX(0,(Premissas!$B$52-Premissas!$B$45)/Premissas!$B$32)) -> 97.276265 | C21: lojas
A22: % da rede de hoje — só os planos | B22: =IF(Premissas!$B$39=0,0,B20/Premissas!$B$39) -> 0.31597859 | C22: %
A23: % da rede de hoje — com o Painel | B23: =IF(Premissas!$B$39=0,0,B21/Premissas!$B$39) -> 0.22569899 | C23: %
A25: ECONOMIA UNITÁRIA
A26: Ticket médio | B26: =Premissas!$B$9 -> 299 | C26: R$/mês
A27: Custo variável por loja | B27: =Premissas!$B$31 -> 42 | C27: R$/mês
A28: Margem de contribuição | B28: =Premissas!$B$32 -> 257 | C28: R$/mês
A29: Margem de contribuição % | B29: =Premissas!$B$32/Premissas!$B$9 -> 0.85953177 | C29: %
A30: Payback do CAC | B30: =IF(Premissas!$B$32=0,0,Premissas!$B$13/Premissas!$B$32) -> 0.19455253 | C30: meses | D30: Quantos meses uma loja leva para devolver o custo de tê-la conquistado.
A31: LTV | B31: =IF(Premissas!$B$36=0,0,Premissas!$B$32/Premissas!$B$36) -> 17133.333 | C31: R$ | D31: Margem de contribuição dividida pelo churn mensal.
A32: LTV / CAC | B32: =IF(Premissas!$B$13=0,0,B31/Premissas!$B$13) -> 342.66667 | C32: x | D32: Acima de 3x já é saudável. Um número muito alto aqui não é sorte: diz que o risco deste negócio não está em conquistar cliente, está no canal.
A34: Este resumo está antes dos impostos se a alíquota em Premissas estiver zerada (item N3).

Sheet Cenários
A1: Cenários
A2: Cada cenário recalcula os 36 meses com suas próprias premissas. Os valores em branco herdam a aba Premissas.
A4: PREMISSAS DE CADA CENÁRIO
A5: Cenário | B5: Preço por loja | C5: Teto de adoção | D5: Atraso (meses) | E5: Participação franqueadora | F5: Painel da Rede | G5: Custo fixo em regime | H5: CAC por loja | I5: Mês central | J5: Custo variável | K5: Inclinação
A6: 1 · SEM homologação — venda loja a loja | B6: =Premissas!$C$9 -> 319 | C6: =Premissas!$C$10 -> 0.65 | D6: =Premissas!$B$42 -> 0 | E6: =Premissas!$C$15 -> 0 | F6: =Premissas!$B$45 -> 10000 | G6: =Premissas!$B$52 -> 35000 | H6: =Premissas!$C$13 -> 400 | I6: =Premissas!$C$11 -> 16 | J6: =Premissas!$B$66 -> 45 | K6: =Premissas!$C$12 -> 0.32
A7: 2 · COM homologação — obrigatório, participação 25% | B7: =Premissas!$D$9 -> 299 | C7: =Premissas!$D$10 -> 0.95 | D7: =Premissas!$B$42 -> 0 | E7: =Premissas!$D$15 -> 0.25 | F7: =Premissas!$B$45 -> 10000 | G7: =Premissas!$B$52 -> 35000 | H7: =Premissas!$D$13 -> 50 | I7: =Premissas!$D$11 -> 12 | J7: =Premissas!$B$67 -> 42 | K7: =Premissas!$D$12 -> 0.45
A8: Com homologação · sem participação | B8: =Premissas!$D$9 -> 299 | C8: =Premissas!$D$10 -> 0.95 | D8: =Premissas!$B$42 -> 0 | E8: 0 | F8: =Premissas!$B$45 -> 10000 | G8: =Premissas!$B$52 -> 35000 | H8: =Premissas!$D$13 -> 50 | I8: =Premissas!$D$11 -> 12 | J8: =Premissas!$B$67 -> 42 | K8: =Premissas!$D$12 -> 0.45
A9: Com homologação · participação 20% | B9: =Premissas!$D$9 -> 299 | C9: =Premissas!$D$10 -> 0.95 | D9: =Premissas!$B$42 -> 0 | E9: 0.2 | F9: =Premissas!$B$45 -> 10000 | G9: =Premissas!$B$52 -> 35000 | H9: =Premissas!$D$13 -> 50 | I9: =Premissas!$D$11 -> 12 | J9: =Premissas!$B$67 -> 42 | K9: =Premissas!$D$12 -> 0.45
A10: Com homologação · participação 30% | B10: =Premissas!$D$9 -> 299 | C10: =Premissas!$D$10 -> 0.95 | D10: =Premissas!$B$42 -> 0 | E10: 0.3 | F10: =Premissas!$B$45 -> 10000 | G10: =Premissas!$B$52 -> 35000 | H10: =Premissas!$D$13 -> 50 | I10: =Premissas!$D$11 -> 12 | J10: =Premissas!$B$67 -> 42 | K10: =Premissas!$D$12 -> 0.45
A11: Com homologação · participação 40% | B11: =Premissas!$D$9 -> 299 | C11: =Premissas!$D$10 -> 0.95 | D11: =Premissas!$B$42 -> 0 | E11: 0.4 | F11: =Premissas!$B$45 -> 10000 | G11: =Premissas!$B$52 -> 35000 | H11: =Premissas!$D$13 -> 50 | I11: =Premissas!$D$11 -> 12 | J11: =Premissas!$B$67 -> 42 | K11: =Premissas!$D$12 -> 0.45
A12: Com homologação · preço R$ 249 · particip. 25% | B12: 249 | C12: =Premissas!$D$10 -> 0.95 | D12: =Premissas!$B$42 -> 0 | E12: =Premissas!$D$15 -> 0.25 | F12: =Premissas!$B$45 -> 10000 | G12: =Premissas!$B$52 -> 35000 | H12: =Premissas!$D$13 -> 50 | I12: =Premissas!$D$11 -> 12 | J12: =Premissas!$B$67 -> 42 | K12: =Premissas!$D$12 -> 0.45
A13: Com homologação · atraso de 6 meses | B13: =Premissas!$D$9 -> 299 | C13: =Premissas!$D$10 -> 0.95 | D13: 6 | E13: =Premissas!$D$15 -> 0.25 | F13: =Premissas!$B$45 -> 10000 | G13: =Premissas!$B$52 -> 35000 | H13: =Premissas!$D$13 -> 50 | I13: =Premissas!$D$11 -> 12 | J13: =Premissas!$B$67 -> 42 | K13: =Premissas!$D$12 -> 0.45
A14: Com homologação · enxuta, sem pró-labore | B14: =Premissas!$D$9 -> 299 | C14: =Premissas!$D$10 -> 0.95 | D14: =Premissas!$B$42 -> 0 | E14: =Premissas!$D$15 -> 0.25 | F14: =Premissas!$B$45 -> 10000 | G14: 25000 | H14: =Premissas!$D$13 -> 50 | I14: =Premissas!$D$11 -> 12 | J14: =Premissas!$B$67 -> 42 | K14: =Premissas!$D$12 -> 0.45
A15: Sem homologação · adoção metade da rede | B15: =Premissas!$C$9 -> 319 | C15: 0.325 | D15: =Premissas!$B$42 -> 0 | E15: =Premissas!$C$15 -> 0 | F15: =Premissas!$B$45 -> 10000 | G15: =Premissas!$B$52 -> 35000 | H15: =Premissas!$C$13 -> 400 | I15: =Premissas!$C$11 -> 16 | J15: =Premissas!$B$66 -> 45 | K15: =Premissas!$C$12 -> 0.32
A16: Sem homologação · participação de 35% | B16: =Premissas!$C$9 -> 319 | C16: =Premissas!$C$10 -> 0.65 | D16: =Premissas!$B$42 -> 0 | E16: 0.35 | F16: =Premissas!$B$45 -> 10000 | G16: =Premissas!$B$52 -> 35000 | H16: =Premissas!$C$13 -> 400 | I16: =Premissas!$C$11 -> 16 | J16: =Premissas!$B$66 -> 45 | K16: =Premissas!$C$12 -> 0.32
A17: Sem homologação · pior caso combinado | B17: =Premissas!$C$9 -> 319 | C17: 0.325 | D17: 6 | E17: 0.35 | F17: =Premissas!$B$45 -> 10000 | G17: =Premissas!$B$52 -> 35000 | H17: =Premissas!$C$13 -> 400 | I17: =Premissas!$C$11 -> 16 | J17: =Premissas!$B$66 -> 45 | K17: =Premissas!$C$12 -> 0.32
A19: RESULTADO DE CADA CENÁRIO
A20: Cenário | B20: 1º mês positivo | C20: Caixa volta a zero | D20: Capital necessário | E20: Receita ano 3 | F20: Resultado ano 3 | G20: Lojas no mês 36
A21: 1 · SEM homologação — venda loja a loja | B21: =IF(MIN(H42:H77)=9999,0,MIN(H42:H77)) -> 15 | C21: =IF(MIN(I42:I77)=9999,0,MIN(I42:I77)) -> 23 | D21: =-MIN(G42:G77) -> 267088.27 | E21: =SUM(D66:D77) -> 1526137.2 | F21: =SUM(F66:F77) -> 883248.22 | G21: =C77 -> 389.35307
A22: 2 · COM homologação — obrigatório, participação 25% | B22: =IF(MIN(O42:O77)=9999,0,MIN(O42:O77)) -> 11 | C22: =IF(MIN(P42:P77)=9999,0,MIN(P42:P77)) -> 17 | D22: =-MIN(N42:N77) -> 191609.42 | E22: =SUM(K66:K77) -> 1556927.8 | F22: =SUM(M66:M77) -> 859394.1 | G22: =J77 -> 569.98837
A23: Com homologação · sem participação | B23: =IF(MIN(V42:V77)=9999,0,MIN(V42:V77)) -> 10 | C23: =IF(MIN(W42:W77)=9999,0,MIN(W42:W77)) -> 15 | D23: =-MIN(U42:U77) -> 168814.81 | E23: =SUM(R66:R77) -> 2075903.7 | F23: =SUM(T66:T77) -> 1378370 | G23: =Q77 -> 569.98837
A24: Com homologação · participação 20% | B24: =IF(MIN(AC42:AC77)=9999,0,MIN(AC42:AC77)) -> 11 | C24: =IF(MIN(AD42:AD77)=9999,0,MIN(AD42:AD77)) -> 17 | D24: =-MIN(AB42:AB77) -> 185691.49 | E24: =SUM(Y66:Y77) -> 1660723 | F24: =SUM(AA66:AA77) -> 963189.29 | G24: =X77 -> 569.98837
A25: Com homologação · participação 30% | B25: =IF(MIN(AJ42:AJ77)=9999,0,MIN(AJ42:AJ77)) -> 12 | C25: =IF(MIN(AK42:AK77)=9999,0,MIN(AK42:AK77)) -> 18 | D25: =-MIN(AI42:AI77) -> 198024.28 | E25: =SUM(AF66:AF77) -> 1453132.6 | F25: =SUM(AH66:AH77) -> 755598.92 | G25: =AE77 -> 569.98837
A26: Com homologação · participação 40% | B26: =IF(MIN(AQ42:AQ77)=9999,0,MIN(AQ42:AQ77)) -> 12 | C26: =IF(MIN(AR42:AR77)=9999,0,MIN(AR42:AR77)) -> 21 | D26: =-MIN(AP42:AP77) -> 216198.03 | E26: =SUM(AM66:AM77) -> 1245542.2 | F26: =SUM(AO66:AO77) -> 548008.54 | G26: =AL77 -> 569.98837
A27: Com homologação · preço R$ 249 · particip. 25% | B27: =IF(MIN(AX42:AX77)=9999,0,MIN(AX42:AX77)) -> 12 | C27: =IF(MIN(AY42:AY77)=9999,0,MIN(AY42:AY77)) -> 20 | D27: =-MIN(AW42:AW77) -> 207968.03 | E27: =SUM(AT66:AT77) -> 1311622.1 | F27: =SUM(AV66:AV77) -> 614088.45 | G27: =AS77 -> 569.98837
A28: Com homologação · atraso de 6 meses | B28: =IF(MIN(BE42:BE77)=9999,0,MIN(BE42:BE77)) -> 17 | C28: =IF(MIN(BF42:BF77)=9999,0,MIN(BF42:BF77)) -> 23 | D28: =-MIN(BD42:BD77) -> 218425.8 | E28: =SUM(BA66:BA77) -> 1544262.5 | F28: =SUM(BC66:BC77) -> 847598.82 | G28: =AZ77 -> 569.82704
A29: Com homologação · enxuta, sem pró-labore | B29: =IF(MIN(BL42:BL77)=9999,0,MIN(BL42:BL77)) -> 10 | C29: =IF(MIN(BM42:BM77)=9999,0,MIN(BM42:BM77)) -> 16 | D29: =-MIN(BK42:BK77) -> 176094.09 | E29: =SUM(BH66:BH77) -> 1556927.8 | F29: =SUM(BJ66:BJ77) -> 979394.1 | G29: =BG77 -> 569.98837
A30: Sem homologação · adoção metade da rede | B30: =IF(MIN(BS42:BS77)=9999,0,MIN(BS42:BS77)) -> 19 | C30: =IF(MIN(BT42:BT77)=9999,0,MIN(BT42:BT77)) -> 35 | D30: =-MIN(BR42:BR77) -> 327401.78 | E30: =SUM(BO66:BO77) -> 823068.6 | F30: =SUM(BQ66:BQ77) -> 291624.11 | G30: =BN77 -> 194.67653
A31: Sem homologação · participação de 35% | B31: =IF(MIN(BZ42:BZ77)=9999,0,MIN(BZ42:BZ77)) -> 19 | C31: =IF(MIN(CA42:CA77)=9999,0,MIN(CA42:CA77)) -> 35 | D31: =-MIN(BY42:BY77) -> 377326.21 | E31: =SUM(BV66:BV77) -> 991989.18 | F31: =SUM(BX66:BX77) -> 349100.21 | G31: =BU77 -> 389.35307
A32: Sem homologação · pior caso combinado | B32: =IF(MIN(CG42:CG77)=9999,0,MIN(CG42:CG77)) -> 33 | C32: =IF(MIN(CH42:CH77)=9999,0,MIN(CH42:CH77)) -> 0 | D32: =-MIN(CF42:CF77) -> 500221.33 | E32: =SUM(CC66:CC77) -> 499736.42 | F32: =SUM(CE66:CE77) -> -42640.764 | G32: =CB77 -> 192.81475
A34: Zero em "1º mês positivo" ou "caixa volta a zero" significa que não acontece dentro dos 36 meses. A receita já está líquida de participação e de impostos.
A36: AS DUAS LINHAS EM DESTAQUE SÃO A DECISÃO. Sem homologação: você vende loja a loja, a R$ 319, e chega a 65% da rede. Com homologação: a franqueadora torna o produto obrigatório como já fez com Trinks e Sults, cobra das lojas e repassa consolidado — adesão de 95%, preço único de R$ 299, CAC quase nulo, e 25% da receita fica com ela. Todas as outras linhas são sensibilidades em torno dessas duas.
A39: GRADE DE CÁLCULO — 36 meses por cenário (pode ocultar estas linhas)
A40: Mês | C40: 1 · SEM homologação — venda loja a loja | D40: receita | E40: custos | F40: result. | G40: caixa | H40: aux+ | I40: auxcx | J40: 2 · COM homologação — obrigatório, participação 25% | K40: receita | L40: custos | M40: result. | N40: caixa | O40: aux+ | P40: auxcx | Q40: Com homologação · sem participação | R40: receita | S40: custos | T40: result. | U40: caixa | V40: aux+ | W40: auxcx | X40: Com homologação · participação 20% | Y40: receita | Z40: custos | AA40: result. | AB40: caixa | AC40: aux+ | AD40: auxcx | AE40: Com homologação · participação 30% | AF40: receita | AG40: custos | AH40: result. | AI40: caixa | AJ40: aux+ | AK40: auxcx | AL40: Com homologação · participação 40% | AM40: receita | AN40: custos | AO40: result. | AP40: caixa | AQ40: aux+ | AR40: auxcx | AS40: Com homologação · preço R$ 249 · particip. 25% | AT40: receita | AU40: custos | AV40: result. | AW40: caixa | AX40: aux+ | AY40: auxcx | AZ40: Com homologação · atraso de 6 meses | BA40: receita | BB40: custos | BC40: result. | BD40: caixa | BE40: aux+ | BF40: auxcx | BG40: Com homologação · enxuta, sem pró-labore | BH40: receita | BI40: custos | BJ40: result. | BK40: caixa | BL40: aux+ | BM40: auxcx | BN40: Sem homologação · adoção metade da rede | BO40: receita | BP40: custos | BQ40: result. | BR40: caixa | BS40: aux+ | BT40: auxcx | BU40: Sem homologação · participação de 35% | BV40: receita | BW40: custos | BX40: result. | BY40: caixa | BZ40: aux+ | CA40: auxcx | CB40: Sem homologação · pior caso combinado | CC40: receita | CD40: custos | CE40: result. | CF40: caixa | CG40: aux+ | CH40: auxcx
A42: 1 | C42: =IF($A42-$D$6<Premissas!$B$41,0,$C$6*(Premissas!$B$39+(Premissas!$B$40-Premissas!$B$39)*$A42/36)/(1+EXP(-$K$6*($A42-$D$6-$I$6)))) -> 0 | D42: =(C42*$B$6+IF($A42>=Premissas!$B$46+$D$6,$F$6,0))*(1-$E$6)*(1-Premissas!$B$60) -> 0 | E42: =-(C42*$J$6+C42*$H$6+IF($A42-$D$6<=2,Premissas!$B$49,IF($A42-$D$6<=5,Premissas!$B$50,IF($A42-$D$6<=8,Premissas!$B$51,$G$6)))+IF($A42=1+$D$6,Premissas!$B$55,IF($A42=3+$D$6,Premissas!$B$56,IF($A42=6+$D$6,Premissas!$B$57,0)))) -> -13000 | F42: =D42+E42 -> -13000 | G42: =F42 -> -13000 | H42: =IF(F42>0,$A42,9999) -> 9999 | I42: =IF(G42>0,$A42,9999) -> 9999 | J42: =IF($A42-$D$7<Premissas!$B$41,0,$C$7*(Premissas!$B$39+(Premissas!$B$40-Premissas!$B$39)*$A42/36)/(1+EXP(-$K$7*($A42-$D$7-$I$7)))) -> 0 | K42: =(J42*$B$7+IF($A42>=Premissas!$B$46+$D$7,$F$7,0))*(1-$E$7)*(1-Premissas!$B$60) -> 0 | L42: =-(J42*$J$7+J42*$H$7+IF($A42-$D$7<=2,Premissas!$B$49,IF($A42-$D$7<=5,Premissas!$B$50,IF($A42-$D$7<=8,Premissas!$B$51,$G$7)))+IF($A42=1+$D$7,Premissas!$B$55,IF($A42=3+$D$7,Premissas!$B$56,IF($A42=6+$D$7,Premissas!$B$57,0)))) -> -13000 | M42: =K42+L42 -> -13000 | N42: =M42 -> -13000 | O42: =IF(M42>0,$A42,9999) -> 9999 | P42: =IF(N42>0,$A42,9999) -> 9999 | Q42: =IF($A42-$D$8<Premissas!$B$41,0,$C$8*(Premissas!$B$39+(Premissas!$B$40-Premissas!$B$39)*$A42/36)/(1+EXP(-$K$8*($A42-$D$8-$I$8)))) -> 0 | R42: =(Q42*$B$8+IF($A42>=Premissas!$B$46+$D$8,$F$8,0))*(1-$E$8)*(1-Premissas!$B$60) -> 0 | S42: =-(Q42*$J$8+Q42*$H$8+IF($A42-$D$8<=2,Premissas!$B$49,IF($A42-$D$8<=5,Premissas!$B$50,IF($A42-$D$8<=8,Premissas!$B$51,$G$8)))+IF($A42=1+$D$8,Premissas!$B$55,IF($A42=3+$D$8,Premissas!$B$56,IF($A42=6+$D$8,Premissas!$B$57,0)))) -> -13000 | T42: =R42+S42 -> -13000 | U42: =T42 -> -13000 | V42: =IF(T42>0,$A42,9999) -> 9999 | W42: =IF(U42>0,$A42,9999) -> 9999 | X42: =IF($A42-$D$9<Premissas!$B$41,0,$C$9*(Premissas!$B$39+(Premissas!$B$40-Premissas!$B$39)*$A42/36)/(1+EXP(-$K$9*($A42-$D$9-$I$9)))) -> 0 | Y42: =(X42*$B$9+IF($A42>=Premissas!$B$46+$D$9,$F$9,0))*(1-$E$9)*(1-Premissas!$B$60) -> 0 | Z42: =-(X42*$J$9+X42*$H$9+IF($A42-$D$9<=2,Premissas!$B$49,IF($A42-$D$9<=5,Premissas!$B$50,IF($A42-$D$9<=8,Premissas!$B$51,$G$9)))+IF($A42=1+$D$9,Premissas!$B$55,IF($A42=3+$D$9,Premissas!$B$56,IF($A42=6+$D$9,Premissas!$B$57,0)))) -> -13000 | AA42: =Y42+Z42 -> -13000 | AB42: =AA42 -> -13000 | AC42: =IF(AA42>0,$A42,9999) -> 9999 | AD42: =IF(AB42>0,$A42,9999) -> 9999 | AE42: =IF($A42-$D$10<Premissas!$B$41,0,$C$10*(Premissas!$B$39+(Premissas!$B$40-Premissas!$B$39)*$A42/36)/(1+EXP(-$K$10*($A42-$D$10-$I$10)))) -> 0 | AF42: =(AE42*$B$10+IF($A42>=Premissas!$B$46+$D$10,$F$10,0))*(1-$E$10)*(1-Premissas!$B$60) -> 0 | AG42: =-(AE42*$J$10+AE42*$H$10+IF($A42-$D$10<=2,Premissas!$B$49,IF($A42-$D$10<=5,Premissas!$B$50,IF($A42-$D$10<=8,Premissas!$B$51,$G$10)))+IF($A42=1+$D$10,Premissas!$B$55,IF($A42=3+$D$10,Premissas!$B$56,IF($A42=6+$D$10,Premissas!$B$57,0)))) -> -13000 | AH42: =AF42+AG42 -> -13000 | AI42: =AH42 -> -13000 | AJ42: =IF(AH42>0,$A42,9999) -> 9999 | AK42: =IF(AI42>0,$A42,9999) -> 9999 | AL42: =IF($A42-$D$11<Premissas!$B$41,0,$C$11*(Premissas!$B$39+(Premissas!$B$40-Premissas!$B$39)*$A42/36)/(1+EXP(-$K$11*($A42-$D$11-$I$11)))) -> 0 | AM42: =(AL42*$B$11+IF($A42>=Premissas!$B$46+$D$11,$F$11,0))*(1-$E$11)*(1-Premissas!$B$60) -> 0 | AN42: =-(AL42*$J$11+AL42*$H$11+IF($A42-$D$11<=2,Premissas!$B$49,IF($A42-$D$11<=5,Premissas!$B$50,IF($A42-$D$11<=8,Premissas!$B$51,$G$11)))+IF($A42=1+$D$11,Premissas!$B$55,IF($A42=3+$D$11,Premissas!$B$56,IF($A42=6+$D$11,Premissas!$B$57,0)))) -> -13000 | AO42: =AM42+AN42 -> -13000 | AP42: =AO42 -> -13000 | AQ42: =IF(AO42>0,$A42,9999) -> 9999 | AR42: =IF(AP42>0,$A42,9999) -> 9999 | AS42: =IF($A42-$D$12<Premissas!$B$41,0,$C$12*(Premissas!$B$39+(Premissas!$B$40-Premissas!$B$39)*$A42/36)/(1+EXP(-$K$12*($A42-$D$12-$I$12)))) -> 0 | AT42: =(AS42*$B$12+IF($A42>=Premissas!$B$46+$D$12,$F$12,0))*(1-$E$12)*(1-Premissas!$B$60) -> 0 | AU42: =-(AS42*$J$12+AS42*$H$12+IF($A42-$D$12<=2,Premissas!$B$49,IF($A42-$D$12<=5,Premissas!$B$50,IF($A42-$D$12<=8,Premissas!$B$51,$G$12)))+IF($A42=1+$D$12,Premissas!$B$55,IF($A42=3+$D$12,Premissas!$B$56,IF($A42=6+$D$12,Premissas!$B$57,0)))) -> -13000 | AV42: =AT42+AU42 -> -13000 | AW42: =AV42 -> -13000 | AX42: =IF(AV42>0,$A42,9999) -> 9999 | AY42: =IF(AW42>0,$A42,9999) -> 9999 | AZ42: =IF($A42-$D$13<Premissas!$B$41,0,$C$13*(Premissas!$B$39+(Premissas!$B$40-Premissas!$B$39)*$A42/36)/(1+EXP(-$K$13*($A42-$D$13-$I$13)))) -> 0 | BA42: =(AZ42*$B$13+IF($A42>=Premissas!$B$46+$D$13,$F$13,0))*(1-$E$13)*(1-Premissas!$B$60) -> 0 | BB42: =-(AZ42*$J$13+AZ42*$H$13+IF($A42-$D$13<=2,Premissas!$B$49,IF($A42-$D$13<=5,Premissas!$B$50,IF($A42-$D$13<=8,Premissas!$B$51,$G$13)))+IF($A42=1+$D$13,Premissas!$B$55,IF($A42=3+$D$13,Premissas!$B$56,IF($A42=6+$D$13,Premissas!$B$57,0)))) -> -5000 | BC42: =BA42+BB42 -> -5000 | BD42: =BC42 -> -5000 | BE42: =IF(BC42>0,$A42,9999) -> 9999 | BF42: =IF(BD42>0,$A42,9999) -> 9999 | BG42: =IF($A42-$D$14<Premissas!$B$41,0,$C$14*(Premissas!$B$39+(Premissas!$B$40-Premissas!$B$39)*$A42/36)/(1+EXP(-$K$14*($A42-$D$14-$I$14)))) -> 0 | BH42: =(BG42*$B$14+IF($A42>=Premissas!$B$46+$D$14,$F$14,0))*(1-$E$14)*(1-Premissas!$B$60) -> 0 | BI42: =-(BG42*$J$14+BG42*$H$14+IF($A42-$D$14<=2,Premissas!$B$49,IF($A42-$D$14<=5,Premissas!$B$50,IF($A42-$D$14<=8,Premissas!$B$51,$G$14)))+IF($A42=1+$D$14,Premissas!$B$55,IF($A42=3+$D$14,Premissas!$B$56,IF($A42=6+$D$14,Premissas!$B$57,0)))) -> -13000 | BJ42: =BH42+BI42 -> -13000 | BK42: =BJ42 -> -13000 | BL42: =IF(BJ42>0,$A42,9999) -> 9999 | BM42: =IF(BK42>0,$A42,9999) -> 9999 | BN42: =IF($A42-$D$15<Premissas!$B$41,0,$C$15*(Premissas!$B$39+(Premissas!$B$40-Premissas!$B$39)*$A42/36)/(1+EXP(-$K$15*($A42-$D$15-$I$15)))) -> 0 | BO42: =(BN42*$B$15+IF($A42>=Premissas!$B$46+$D$15,$F$15,0))*(1-$E$15)*(1-Premissas!$B$60) -> 0 | BP42: =-(BN42*$J$15+BN42*$H$15+IF($A42-$D$15<=2,Premissas!$B$49,IF($A42-$D$15<=5,Premissas!$B$50,IF($A42-$D$15<=8,Premissas!$B$51,$G$15)))+IF($A42=1+$D$15,Premissas!$B$55,IF($A42=3+$D$15,Premissas!$B$56,IF($A42=6+$D$15,Premissas!$B$57,0)))) -> -13000 | BQ42: =BO42+BP42 -> -13000 | BR42: =BQ42 -> -13000 | BS42: =IF(BQ42>0,$A42,9999) -> 9999 | BT42: =IF(BR42>0,$A42,9999) -> 9999 | BU42: =IF($A42-$D$16<Premissas!$B$41,0,$C$16*(Premissas!$B$39+(Premissas!$B$40-Premissas!$B$39)*$A42/36)/(1+EXP(-$K$16*($A42-$D$16-$I$16)))) -> 0 | BV42: =(BU42*$B$16+IF($A42>=Premissas!$B$46+$D$16,$F$16,0))*(1-$E$16)*(1-Premissas!$B$60) -> 0 | BW42: =-(BU42*$J$16+BU42*$H$16+IF($A42-$D$16<=2,Premissas!$B$49,IF($A42-$D$16<=5,Premissas!$B$50,IF($A42-$D$16<=8,Premissas!$B$51,$G$16)))+IF($A42=1+$D$16,Premissas!$B$55,IF($A42=3+$D$16,Premissas!$B$56,IF($A42=6+$D$16,Premissas!$B$57,0)))) -> -13000 | BX42: =BV42+BW42 -> -13000 | BY42: =BX42 -> -13000 | BZ42: =IF(BX42>0,$A42,9999) -> 9999 | CA42: =IF(BY42>0,$A42,9999) -> 9999 | CB42: =IF($A42-$D$17<Premissas!$B$41,0,$C$17*(Premissas!$B$39+(Premissas!$B$40-Premissas!$B$39)*$A42/36)/(1+EXP(-$K$17*($A42-$D$17-$I$17)))) -> 0 | CC42: =(CB42*$B$17+IF($A42>=Premissas!$B$46+$D$17,$F$17,0))*(1-$E$17)*(1-Premissas!$B$60) -> 0 | CD42: =-(CB42*$J$17+CB42*$H$17+IF($A42-$D$17<=2,Premissas!$B$49,IF($A42-$D$17<=5,Premissas!$B$50,IF($A42-$D$17<=8,Premissas!$B$51,$G$17)))+IF($A42=1+$D$17,Premissas!$B$55,IF($A42=3+$D$17,Premissas!$B$56,IF($A42=6+$D$17,Premissas!$B$57,0)))) -> -5000 | CE42: =CC42+CD42 -> -5000 | CF42: =CE42 -> -5000 | CG42: =IF(CE42>0,$A42,9999) -> 9999 | CH42: =IF(CF42>0,$A42,9999) -> 9999
A43: 2 | C43: =IF($A43-$D$6<Premissas!$B$41,0,$C$6*(Premissas!$B$39+(Premissas!$B$40-Premissas!$B$39)*$A43/36)/(1+EXP(-$K$6*($A43-$D$6-$I$6)))) -> 0 | D43: =(C43*$B$6+IF($A43>=Premissas!$B$46+$D$6,$F$6,0))*(1-$E$6)*(1-Premissas!$B$60) -> 0 | E43: =-(C43*$J$6+MAX(0,C43-C42)*$H$6+IF($A43-$D$6<=2,Premissas!$B$49,IF($A43-$D$6<=5,Premissas!$B$50,IF($A43-$D$6<=8,Premissas!$B$51,$G$6)))+IF($A43=1+$D$6,Premissas!$B$55,IF($A43=3+$D$6,Premissas!$B$56,IF($A43=6+$D$6,Premissas!$B$57,0)))) -> -5000 | F43: =D43+E43 -> -5000 | G43: =G42+F43 -> -18000 | H43: =IF(F43>0,$A43,9999) -> 9999 | I43: =IF(G43>0,$A43,9999) -> 9999 | J43: =IF($A43-$D$7<Premissas!$B$41,0,$C$7*(Premissas!$B$39+(Premissas!$B$40-Premissas!$B$39)*$A43/36)/(1+EXP(-$K$7*($A43-$D$7-$I$7)))) -> 0 | K43: =(J43*$B$7+IF($A43>=Premissas!$B$46+$D$7,$F$7,0))*(1-$E$7)*(1-Premissas!$B$60) -> 0 | L43: =-(J43*$J$7+MAX(0,J43-J42)*$H$7+IF($A43-$D$7<=2,Premissas!$B$49,IF($A43-$D$7<=5,Premissas!$B$50,IF($A43-$D$7<=8,Premissas!$B$51,$G$7)))+IF($A43=1+$D$7,Premissas!$B$55,IF($A43=3+$D$7,Premissas!$B$56,IF($A43=6+$D$7,Premissas!$B$57,0)))) -> -5000 | M43: =K43+L43 -> -5000 | N43: =N42+M43 -> -18000 | O43: =IF(M43>0,$A43,9999) -> 9999 | P43: =IF(N43>0,$A43,9999) -> 9999 | Q43: =IF($A43-$D$8<Premissas!$B$41,0,$C$8*(Premissas!$B$39+(Premissas!$B$40-Premissas!$B$39)*$A43/36)/(1+EXP(-$K$8*($A43-$D$8-$I$8)))) -> 0 | R43: =(Q43*$B$8+IF($A43>=Premissas!$B$46+$D$8,$F$8,0))*(1-$E$8)*(1-Premissas!$B$60) -> 0 | S43: =-(Q43*$J$8+MAX(0,Q43-Q42)*$H$8+IF($A43-$D$8<=2,Premissas!$B$49,IF($A43-$D$8<=5,Premissas!$B$50,IF($A43-$D$8<=8,Premissas!$B$51,$G$8)))+IF($A43=1+$D$8,Premissas!$B$55,IF($A43=3+$D$8,Premissas!$B$56,IF($A43=6+$D$8,Premissas!$B$57,0)))) -> -5000 | T43: =R43+S43 -> -5000 | U43: =U42+T43 -> -18000 | V43: =IF(T43>0,$A43,9999) -> 9999 | W43: =IF(U43>0,$A43,9999) -> 9999 | X43: =IF($A43-$D$9<Premissas!$B$41,0,$C$9*(Premissas!$B$39+(Premissas!$B$40-Premissas!$B$39)*$A43/36)/(1+EXP(-$K$9*($A43-$D$9-$I$9)))) -> 0 | Y43: =(X43*$B$9+IF($A43>=Premissas!$B$46+$D$9,$F$9,0))*(1-$E$9)*(1-Premissas!$B$60) -> 0 | Z43: =-(X43*$J$9+MAX(0,X43-X42)*$H$9+IF($A43-$D$9<=2,Premissas!$B$49,IF($A43-$D$9<=5,Premissas!$B$50,IF($A43-$D$9<=8,Premissas!$B$51,$G$9)))+IF($A43=1+$D$9,Premissas!$B$55,IF($A43=3+$D$9,Premissas!$B$56,IF($A43=6+$D$9,Premissas!$B$57,0)))) -> -5000 | AA43: =Y43+Z43 -> -5000 | AB43: =AB42+AA43 -> -18000 | AC43: =IF(AA43>0,$A43,9999) -> 9999 | AD43: =IF(AB43>0,$A43,9999) -> 9999 | AE43: =IF($A43-$D$10<Premissas!$B$41,0,$C$10*(Premissas!$B$39+(Premissas!$B$40-Premissas!$B$39)*$A43/36)/(1+EXP(-$K$10*($A43-$D$10-$I$10)))) -> 0 | AF43: =(AE43*$B$10+IF($A43>=Premissas!$B$46+$D$10,$F$10,0))*(1-$E$10)*(1-Premissas!$B$60) -> 0 | AG43: =-(AE43*$J$10+MAX(0,AE43-AE42)*$H$10+IF($A43-$D$10<=2,Premissas!$B$49,IF($A43-$D$10<=5,Premissas!$B$50,IF($A43-$D$10<=8,Premissas!$B$51,$G$10)))+IF($A43=1+$D$10,Premissas!$B$55,IF($A43=3+$D$10,Premissas!$B$56,IF($A43=6+$D$10,Premissas!$B$57,0)))) -> -5000 | AH43: =AF43+AG43 -> -5000 | AI43: =AI42+AH43 -> -18000 | AJ43: =IF(AH43>0,$A43,9999) -> 9999 | AK43: =IF(AI43>0,$A43,9999) -> 9999 | AL43: =IF($A43-$D$11<Premissas!$B$41,0,$C$11*(Premissas!$B$39+(Premissas!$B$40-Premissas!$B$39)*$A43/36)/(1+EXP(-$K$11*($A43-$D$11-$I$11)))) -> 0 | AM43: =(AL43*$B$11+IF($A43>=Premissas!$B$46+$D$11,$F$11,0))*(1-$E$11)*(1-Premissas!$B$60) -> 0 | AN43: =-(AL43*$J$11+MAX(0,AL43-AL42)*$H$11+IF($A43-$D$11<=2,Premissas!$B$49,IF($A43-$D$11<=5,Premissas!$B$50,IF($A43-$D$11<=8,Premissas!$B$51,$G$11)))+IF($A43=1+$D$11,Premissas!$B$55,IF($A43=3+$D$11,Premissas!$B$56,IF($A43=6+$D$11,Premissas!$B$57,0)))) -> -5000 | AO43: =AM43+AN43 -> -5000 | AP43: =AP42+AO43 -> -18000 | AQ43: =IF(AO43>0,$A43,9999) -> 9999 | AR43: =IF(AP43>0,$A43,9999) -> 9999 | AS43: =IF($A43-$D$12<Premissas!$B$41,0,$C$12*(Premissas!$B$39+(Premissas!$B$40-Premissas!$B$39)*$A43/36)/(1+EXP(-$K$12*($A43-$D$12-$I$12)))) -> 0 | AT43: =(AS43*$B$12+IF($A43>=Premissas!$B$46+$D$12,$F$12,0))*(1-$E$12)*(1-Premissas!$B$60) -> 0 | AU43: =-(AS43*$J$12+MAX(0,AS43-AS42)*$H$12+IF($A43-$D$12<=2,Premissas!$B$49,IF($A43-$D$12<=5,Premissas!$B$50,IF($A43-$D$12<=8,Premissas!$B$51,$G$12)))+IF($A43=1+$D$12,Premissas!$B$55,IF($A43=3+$D$12,Premissas!$B$56,IF($A43=6+$D$12,Premissas!$B$57,0)))) -> -5000 | AV43: =AT43+AU43 -> -5000 | AW43: =AW42+AV43 -> -18000 | AX43: =IF(AV43>0,$A43,9999) -> 9999 | AY43: =IF(AW43>0,$A43,9999) -> 9999 | AZ43: =IF($A43-$D$13<Premissas!$B$41,0,$C$13*(Premissas!$B$39+(Premissas!$B$40-Premissas!$B$39)*$A43/36)/(1+EXP(-$K$13*($A43-$D$13-$I$13)))) -> 0 | BA43: =(AZ43*$B$13+IF($A43>=Premissas!$B$46+$D$13,$F$13,0))*(1-$E$13)*(1-Premissas!$B$60) -> 0 | BB43: =-(AZ43*$J$13+MAX(0,AZ43-AZ42)*$H$13+IF($A43-$D$13<=2,Premissas!$B$49,IF($A43-$D$13<=5,Premissas!$B$50,IF($A43-$D$13<=8,Premissas!$B$51,$G$13)))+IF($A43=1+$D$13,Premissas!$B$55,IF($A43=3+$D$13,Premissas!$B$56,IF($A43=6+$D$13,Premissas!$B$57,0)))) -> -5000 | BC43: =BA43+BB43 -> -5000 | BD43: =BD42+BC43 -> -10000 | BE43: =IF(BC43>0,$A43,9999) -> 9999 | BF43: =IF(BD43>0,$A43,9999) -> 9999 | BG43: =IF($A43-$D$14<Premissas!$B$41,0,$C$14*(Premissas!$B$39+(Premissas!$B$40-Premissas!$B$39)*$A43/36)/(1+EXP(-$K$14*($A43-$D$14-$I$14)))) -> 0 | BH43: =(BG43*$B$14+IF($A43>=Premissas!$B$46+$D$14,$F$14,0))*(1-$E$14)*(1-Premissas!$B$60) -> 0 | BI43: =-(BG43*$J$14+MAX(0,BG43-BG42)*$H$14+IF($A43-$D$14<=2,Premissas!$B$49,IF($A43-$D$14<=5,Premissas!$B$50,IF($A43-$D$14<=8,Premissas!$B$51,$G$14)))+IF($A43=1+$D$14,Premissas!$B$55,IF($A43=3+$D$14,Premissas!$B$56,IF($A43=6+$D$14,Premissas!$B$57,0)))) -> -5000 | BJ43: =BH43+BI43 -> -5000 | BK43: =BK42+BJ43 -> -18000 | BL43: =IF(BJ43>0,$A43,9999) -> 9999 | BM43: =IF(BK43>0,$A43,9999) -> 9999 | BN43: =IF($A43-$D$15<Premissas!$B$41,0,$C$15*(Premissas!$B$39+(Premissas!$B$40-Premissas!$B$39)*$A43/36)/(1+EXP(-$K$15*($A43-$D$15-$I$15)))) -> 0 | BO43: =(BN43*$B$15+IF($A43>=Premissas!$B$46+$D$15,$F$15,0))*(1-$E$15)*(1-Premissas!$B$60) -> 0 | BP43: =-(BN43*$J$15+MAX(0,BN43-BN42)*$H$15+IF($A43-$D$15<=2,Premissas!$B$49,IF($A43-$D$15<=5,Premissas!$B$50,IF($A43-$D$15<=8,Premissas!$B$51,$G$15)))+IF($A43=1+$D$15,Premissas!$B$55,IF($A43=3+$D$15,Premissas!$B$56,IF($A43=6+$D$15,Premissas!$B$57,0)))) -> -5000 | BQ43: =BO43+BP43 -> -5000 | BR43: =BR42+BQ43 -> -18000 | BS43: =IF(BQ43>0,$A43,9999) -> 9999 | BT43: =IF(BR43>0,$A43,9999) -> 9999 | BU43: =IF($A43-$D$16<Premissas!$B$41,0,$C$16*(Premissas!$B$39+(Premissas!$B$40-Premissas!$B$39)*$A43/36)/(1+EXP(-$K$16*($A43-$D$16-$I$16)))) -> 0 | BV43: =(BU43*$B$16+IF($A43>=Premissas!$B$46+$D$16,$F$16,0))*(1-$E$16)*(1-Premissas!$B$60) -> 0 | BW43: =-(BU43*$J$16+MAX(0,BU43-BU42)*$H$16+IF($A43-$D$16<=2,Premissas!$B$49,IF($A43-$D$16<=5,Premissas!$B$50,IF($A43-$D$16<=8,Premissas!$B$51,$G$16)))+IF($A43=1+$D$16,Premissas!$B$55,IF($A43=3+$D$16,Premissas!$B$56,IF($A43=6+$D$16,Premissas!$B$57,0)))) -> -5000 | BX43: =BV43+BW43 -> -5000 | BY43: =BY42+BX43 -> -18000 | BZ43: =IF(BX43>0,$A43,9999) -> 9999 | CA43: =IF(BY43>0,$A43,9999) -> 9999 | CB43: =IF($A43-$D$17<Premissas!$B$41,0,$C$17*(Premissas!$B$39+(Premissas!$B$40-Premissas!$B$39)*$A43/36)/(1+EXP(-$K$17*($A43-$D$17-$I$17)))) -> 0 | CC43: =(CB43*$B$17+IF($A43>=Premissas!$B$46+$D$17,$F$17,0))*(1-$E$17)*(1-Premissas!$B$60) -> 0 | CD43: =-(CB43*$J$17+MAX(0,CB43-CB42)*$H$17+IF($A43-$D$17<=2,Premissas!$B$49,IF($A43-$D$17<=5,Premissas!$B$50,IF($A43-$D$17<=8,Premissas!$B$51,$G$17)))+IF($A43=1+$D$17,Premissas!$B$55,IF($A43=3+$D$17,Premissas!$B$56,IF($A43=6+$D$17,Premissas!$B$57,0)))) -> -5000 | CE43: =CC43+CD43 -> -5000 | CF43: =CF42+CE43 -> -10000 | CG43: =IF(CE43>0,$A43,9999) -> 9999 | CH43: =IF(CF43>0,$A43,9999) -> 9999
A44: 3 | C44: =IF($A44-$D$6<Premissas!$B$41,0,$C$6*(Premissas!$B$39+(Premissas!$B$40-Premissas!$B$39)*$A44/36)/(1+EXP(-$K$6*($A44-$D$6-$I$6)))) -> 0 | D44: =(C44*$B$6+IF($A44>=Premissas!$B$46+$D$6,$F$6,0))*(1-$E$6)*(1-Premissas!$B$60) -> 0 | E44: =-(C44*$J$6+MAX(0,C44-C43)*$H$6+IF($A44-$D$6<=2,Premissas!$B$49,IF($A44-$D$6<=5,Premissas!$B$50,IF($A44-$D$6<=8,Premissas!$B$51,$G$6)))+IF($A44=1+$D$6,Premissas!$B$55,IF($A44=3+$D$6,Premissas!$B$56,IF($A44=6+$D$6,Premissas!$B$57,0)))) -> -34000 | F44: =D44+E44 -> -34000 | G44: =G43+F44 -> -52000 | H44: =IF(F44>0,$A44,9999) -> 9999 | I44: =IF(G44>0,$A44,9999) -> 9999 | J44: =IF($A44-$D$7<Premissas!$B$41,0,$C$7*(Premissas!$B$39+(Premissas!$B$40-Premissas!$B$39)*$A44/36)/(1+EXP(-$K$7*($A44-$D$7-$I$7)))) -> 0 | K44: =(J44*$B$7+IF($A44>=Premissas!$B$46+$D$7,$F$7,0))*(1-$E$7)*(1-Premissas!$B$60) -> 0 | L44: =-(J44*$J$7+MAX(0,J44-J43)*$H$7+IF($A44-$D$7<=2,Premissas!$B$49,IF($A44-$D$7<=5,Premissas!$B$50,IF($A44-$D$7<=8,Premissas!$B$51,$G$7)))+IF($A44=1+$D$7,Premissas!$B$55,IF($A44=3+$D$7,Premissas!$B$56,IF($A44=6+$D$7,Premissas!$B$57,0)))) -> -34000 | M44: =K44+L44 -> -34000 | N44: =N43+M44 -> -52000 | O44: =IF(M44>0,$A44,9999) -> 9999 | P44: =IF(N44>0,$A44,9999) -> 9999 | Q44: =IF($A44-$D$8<Premissas!$B$41,0,$C$8*(Premissas!$B$39+(Premissas!$B$40-Premissas!$B$39)*$A44/36)/(1+EXP(-$K$8*($A44-$D$8-$I$8)))) -> 0 | R44: =(Q44*$B$8+IF($A44>=Premissas!$B$46+$D$8,$F$8,0))*(1-$E$8)*(1-Premissas!$B$60) -> 0 | S44: =-(Q44*$J$8+MAX(0,Q44-Q43)*$H$8+IF($A44-$D$8<=2,Premissas!$B$49,IF($A44-$D$8<=5,Premissas!$B$50,IF($A44-$D$8<=8,Premissas!$B$51,$G$8)))+IF($A44=1+$D$8,Premissas!$B$55,IF($A44=3+$D$8,Premissas!$B$56,IF($A44=6+$D$8,Premissas!$B$57,0)))) -> -34000 | T44: =R44+S44 -> -34000 | U44: =U43+T44 -> -52000 | V44: =IF(T44>0,$A44,9999) -> 9999 | W44: =IF(U44>0,$A44,9999) -> 9999 | X44: =IF($A44-$D$9<Premissas!$B$41,0,$C$9*(Premissas!$B$39+(Premissas!$B$40-Premissas!$B$39)*$A44/36)/(1+EXP(-$K$9*($A44-$D$9-$I$9)))) -> 0 | Y44: =(X44*$B$9+IF($A44>=Premissas!$B$46+$D$9,$F$9,0))*(1-$E$9)*(1-Premissas!$B$60) -> 0 | Z44: =-(X44*$J$9+MAX(0,X44-X43)*$H$9+IF($A44-$D$9<=2,Premissas!$B$49,IF($A44-$D$9<=5,Premissas!$B$50,IF($A44-$D$9<=8,Premissas!$B$51,$G$9)))+IF($A44=1+$D$9,Premissas!$B$55,IF($A44=3+$D$9,Premissas!$B$56,IF($A44=6+$D$9,Premissas!$B$57,0)))) -> -34000 | AA44: =Y44+Z44 -> -34000 | AB44: =AB43+AA44 -> -52000 | AC44: =IF(AA44>0,$A44,9999) -> 9999 | AD44: =IF(AB44>0,$A44,9999) -> 9999 | AE44: =IF($A44-$D$10<Premissas!$B$41,0,$C$10*(Premissas!$B$39+(Premissas!$B$40-Premissas!$B$39)*$A44/36)/(1+EXP(-$K$10*($A44-$D$10-$I$10)))) -> 0 | AF44: =(AE44*$B$10+IF($A44>=Premissas!$B$46+$D$10,$F$10,0))*(1-$E$10)*(1-Premissas!$B$60) -> 0 | AG44: =-(AE44*$J$10+MAX(0,AE44-AE43)*$H$10+IF($A44-$D$10<=2,Premissas!$B$49,IF($A44-$D$10<=5,Premissas!$B$50,IF($A44-$D$10<=8,Premissas!$B$51,$G$10)))+IF($A44=1+$D$10,Premissas!$B$55,IF($A44=3+$D$10,Premissas!$B$56,IF($A44=6+$D$10,Premissas!$B$57,0)))) -> -34000 | AH44: =AF44+AG44 -> -34000 | AI44: =AI43+AH44 -> -52000 | AJ44: =IF(AH44>0,$A44,9999) -> 9999 | AK44: =IF(AI44>0,$A44,9999) -> 9999 | AL44: =IF($A44-$D$11<Premissas!$B$41,0,$C$11*(Premissas!$B$39+(Premissas!$B$40-Premissas!$B$39)*$A44/36)/(1+EXP(-$K$11*($A44-$D$11-$I$11)))) -> 0 | AM44: =(AL44*$B$11+IF($A44>=Premissas!$B$46+$D$11,$F$11,0))*(1-$E$11)*(1-Premissas!$B$60) -> 0 | AN44: =-(AL44*$J$11+MAX(0,AL44-AL43)*$H$11+IF($A44-$D$11<=2,Premissas!$B$49,IF($A44-$D$11<=5,Premissas!$B$50,IF($A44-$D$11<=8,Premissas!$B$51,$G$11)))+IF($A44=1+$D$11,Premissas!$B$55,IF($A44=3+$D$11,Premissas!$B$56,IF($A44=6+$D$11,Premissas!$B$57,0)))) -> -34000 | AO44: =AM44+AN44 -> -34000 | AP44: =AP43+AO44 -> -52000 | AQ44: =IF(AO44>0,$A44,9999) -> 9999 | AR44: =IF(AP44>0,$A44,9999) -> 9999 | AS44: =IF($A44-$D$12<Premissas!$B$41,0,$C$12*(Premissas!$B$39+(Premissas!$B$40-Premissas!$B$39)*$A44/36)/(1+EXP(-$K$12*($A44-$D$12-$I$12)))) -> 0 | AT44: =(AS44*$B$12+IF($A44>=Premissas!$B$46+$D$12,$F$12,0))*(1-$E$12)*(1-Premissas!$B$60) -> 0 | AU44: =-(AS44*$J$12+MAX(0,AS44-AS43)*$H$12+IF($A44-$D$12<=2,Premissas!$B$49,IF($A44-$D$12<=5,Premissas!$B$50,IF($A44-$D$12<=8,Premissas!$B$51,$G$12)))+IF($A44=1+$D$12,Premissas!$B$55,IF($A44=3+$D$12,Premissas!$B$56,IF($A44=6+$D$12,Premissas!$B$57,0)))) -> -34000 | AV44: =AT44+AU44 -> -34000 | AW44: =AW43+AV44 -> -52000 | AX44: =IF(AV44>0,$A44,9999) -> 9999 | AY44: =IF(AW44>0,$A44,9999) -> 9999 | AZ44: =IF($A44-$D$13<Premissas!$B$41,0,$C$13*(Premissas!$B$39+(Premissas!$B$40-Premissas!$B$39)*$A44/36)/(1+EXP(-$K$13*($A44-$D$13-$I$13)))) -> 0 | BA44: =(AZ44*$B$13+IF($A44>=Premissas!$B$46+$D$13,$F$13,0))*(1-$E$13)*(1-Premissas!$B$60) -> 0 | BB44: =-(AZ44*$J$13+MAX(0,AZ44-AZ43)*$H$13+IF($A44-$D$13<=2,Premissas!$B$49,IF($A44-$D$13<=5,Premissas!$B$50,IF($A44-$D$13<=8,Premissas!$B$51,$G$13)))+IF($A44=1+$D$13,Premissas!$B$55,IF($A44=3+$D$13,Premissas!$B$56,IF($A44=6+$D$13,Premissas!$B$57,0)))) -> -5000 | BC44: =BA44+BB44 -> -5000 | BD44: =BD43+BC44 -> -15000 | BE44: =IF(BC44>0,$A44,9999) -> 9999 | BF44: =IF(BD44>0,$A44,9999) -> 9999 | BG44: =IF($A44-$D$14<Premissas!$B$41,0,$C$14*(Premissas!$B$39+(Premissas!$B$40-Premissas!$B$39)*$A44/36)/(1+EXP(-$K$14*($A44-$D$14-$I$14)))) -> 0 | BH44: =(BG44*$B$14+IF($A44>=Premissas!$B$46+$D$14,$F$14,0))*(1-$E$14)*(1-Premissas!$B$60) -> 0 | BI44: =-(BG44*$J$14+MAX(0,BG44-BG43)*$H$14+IF($A44-$D$14<=2,Premissas!$B$49,IF($A44-$D$14<=5,Premissas!$B$50,IF($A44-$D$14<=8,Premissas!$B$51,$G$14)))+IF($A44=1+$D$14,Premissas!$B$55,IF($A44=3+$D$14,Premissas!$B$56,IF($A44=6+$D$14,Premissas!$B$57,0)))) -> -34000 | BJ44: =BH44+BI44 -> -34000 | BK44: =BK43+BJ44 -> -52000 | BL44: =IF(BJ44>0,$A44,9999) -> 9999 | BM44: =IF(BK44>0,$A44,9999) -> 9999 | BN44: =IF($A44-$D$15<Premissas!$B$41,0,$C$15*(Premissas!$B$39+(Premissas!$B$40-Premissas!$B$39)*$A44/36)/(1+EXP(-$K$15*($A44-$D$15-$I$15)))) -> 0 | BO44: =(BN44*$B$15+IF($A44>=Premissas!$B$46+$D$15,$F$15,0))*(1-$E$15)*(1-Premissas!$B$60) -> 0 | BP44: =-(BN44*$J$15+MAX(0,BN44-BN43)*$H$15+IF($A44-$D$15<=2,Premissas!$B$49,IF($A44-$D$15<=5,Premissas!$B$50,IF($A44-$D$15<=8,Premissas!$B$51,$G$15)))+IF($A44=1+$D$15,Premissas!$B$55,IF($A44=3+$D$15,Premissas!$B$56,IF($A44=6+$D$15,Premissas!$B$57,0)))) -> -34000 | BQ44: =BO44+BP44 -> -34000 | BR44: =BR43+BQ44 -> -52000 | BS44: =IF(BQ44>0,$A44,9999) -> 9999 | BT44: =IF(BR44>0,$A44,9999) -> 9999 | BU44: =IF($A44-$D$16<Premissas!$B$41,0,$C$16*(Premissas!$B$39+(Premissas!$B$40-Premissas!$B$39)*$A44/36)/(1+EXP(-$K$16*($A44-$D$16-$I$16)))) -> 0 | BV44: =(BU44*$B$16+IF($A44>=Premissas!$B$46+$D$16,$F$16,0))*(1-$E$16)*(1-Premissas!$B$60) -> 0 | BW44: =-(BU44*$J$16+MAX(0,BU44-BU43)*$H$16+IF($A44-$D$16<=2,Premissas!$B$49,IF($A44-$D$16<=5,Premissas!$B$50,IF($A44-$D$16<=8,Premissas!$B$51,$G$16)))+IF($A44=1+$D$16,Premissas!$B$55,IF($A44=3+$D$16,Premissas!$B$56,IF($A44=6+$D$16,Premissas!$B$57,0)))) -> -34000 | BX44: =BV44+BW44 -> -34000 | BY44: =BY43+BX44 -> -52000 | BZ44: =IF(BX44>0,$A44,9999) -> 9999 | CA44: =IF(BY44>0,$A44,9999) -> 9999 | CB44: =IF($A44-$D$17<Premissas!$B$41,0,$C$17*(Premissas!$B$39+(Premissas!$B$40-Premissas!$B$39)*$A44/36)/(1+EXP(-$K$17*($A44-$D$17-$I$17)))) -> 0 | CC44: =(CB44*$B$17+IF($A44>=Premissas!$B$46+$D$17,$F$17,0))*(1-$E$17)*(1-Premissas!$B$60) -> 0 | CD44: =-(CB44*$J$17+MAX(0,CB44-CB43)*$H$17+IF($A44-$D$17<=2,Premissas!$B$49,IF($A44-$D$17<=5,Premissas!$B$50,IF($A44-$D$17<=8,Premissas!$B$51,$G$17)))+IF($A44=1+$D$17,Premissas!$B$55,IF($A44=3+$D$17,Premissas!$B$56,IF($A44=6+$D$17,Premissas!$B$57,0)))) -> -5000 | CE44: =CC44+CD44 -> -5000 | CF44: =CF43+CE44 -> -15000 | CG44: =IF(CE44>0,$A44,9999) -> 9999 | CH44: =IF(CF44>0,$A44,9999) -> 9999
